Workbook

Sheet Main
A2: Recipe DB
A3: recipes | B3: ingrediants | C3: quantity | D3: unit | E3: prep_time | F3: cooking_time | G3: serving | H3: book_title | I3: chef | J3: published_date | K3: Course
A4: Berbere spiced chicken | B4: onion | C4: 1 | D4: each | E4: 0.017361111 | F4: 0.059027778 | G4: 4 to 6 | H4: Ottolenghi Test Kitchen | I4: Yotam Ottolenghi | J4: 44483 | K4: Main
A5: =A4 -> Berbere spiced chicken | B5: garlic clove | C5: 6 | D5: clove
A6: =A5 -> Berbere spiced chicken | B6: coriander | C6: 45 | D6: g
A7: =A6 -> Berbere spiced chicken | B7: berbere spice | C7: 2.5 | D7: tbsp
A8: =A7 -> Berbere spiced chicken | B8: tomato paste | C8: 2 | D8: tbsp
A9: =A8 -> Berbere spiced chicken | B9: honey | C9: 2.5 | D9: tbsp
A10: =A9 -> Berbere spiced chicken | B10: apple cider vinegar | C10: 3 | D10: tbsp
A11: =A10 -> Berbere spiced chicken | B11: olive oil | C11: 90 | D11: ml
A12: =A11 -> Berbere spiced chicken | B12: carrots | C12: 800 | D12: g
A13: =A12 -> Berbere spiced chicken | B13: tinned chickpeas | C13: 2 | D13: tin
A14: =A13 -> Berbere spiced chicken | B14: chicken thigh | C14: 8 | D14: piece
A15: =A14 -> Berbere spiced chicken | B15: oranges | C15: 3 | D15: each
A16: =A15 -> Berbere spiced chicken | B16: salt | C16: 0.1 | D16: tsp
A17: =A16 -> Berbere spiced chicken | B17: black pepper | C17: 0.1 | D17: tsp
A18: Zaatar salmon | B18: salmon fillet | C18: 4 | D18: piece | E18: 0.0034722222 | F18: 0.013888889 | G18: 4 | H18: Ottolenghi Test Kitchen | I18: Yotam Ottolenghi | J18: 44483 | K18: Main
A19: =A18 -> Zaatar salmon | B19: zaatar | C19: 15 | D19: g
A20: =A19 -> Zaatar salmon | B20: sumac | C20: 10 | D20: g
A21: =A20 -> Zaatar salmon | B21: olive oil | C21: 60 | D21: ml
A22: =A21 -> Zaatar salmon | B22: baby spinach | C22: 250 | D22: g
A23: =A22 -> Zaatar salmon | B23: tahini | C23: 90 | D23: g
A24: =A23 -> Zaatar salmon | B24: garlic clove | C24: 3 | D24: clove
A25: =A24 -> Zaatar salmon | B25: lemon juice | C25: 3.5 | D25: tbsp
A26: =A25 -> Zaatar salmon | B26: coriander | C26: 10 | D26: g
A27: =A26 -> Zaatar salmon | B27: salt | C27: 0.1 | D27: tsp
A28: =A27 -> Zaatar salmon | B28: black pepper | C28: 0.1 | D28: tsp
A29: Baked mint rice | B29: basmati rice | C29: 400 | D29: g | E29: 0.0034722222 | F29: 0.017361111 | G29: 6 | H29: Ottolenghi SIMPLE | I29: Yotam Ottolenghi | J29: 43377 | K29: Main / Side
A30: =A29 -> Baked mint rice | B30: unsalted butter | C30: 50 | D30: g
A31: =A30 -> Baked mint rice | B31: boiling water | C31: 800 | D31: ml
A32: =A31 -> Baked mint rice | B32: mint | C32: 50 | D32: g
A33: =A32 -> Baked mint rice | B33: feta | C33: 150 | D33: g
A34: =A33 -> Baked mint rice | B34: salt | C34: 0.1 | D34: tsp
A35: =A34 -> Baked mint rice | B35: black pepper | C35: 0.1 | D35: tsp
A36: =A35 -> Baked mint rice | B36: pitted green olives | C36: 40 | D36: g
A37: =A36 -> Baked mint rice | B37: pomegranate seeds | C37: 90 | D37: g
A38: =A37 -> Baked mint rice | B38: walnut | C38: 50 | D38: g
A39: =A38 -> Baked mint rice | B39: olive oil | C39: 45 | D39: ml
A40: =A39 -> Baked mint rice | B40: pomegranate molasses | C40: 1 | D40: tbsp
A41: =A40 -> Baked mint rice | B41: garlic clove | C41: 1 | D41: clove
...

Sheet others
A1: ingredient_type | B1: ingredient_type_id | D1: unit_abbreviation | E1: unit_id | G1: ingredients | H1: ingredient_type
A2: Meat | B2: 1 | D2: g | E2: 1 | G2: onion | H2: Vegetables
A3: Seafood | B3: 2 | D3: kg | E3: 2 | G3: garlic clove | H3: Vegetables
A4: Vegetables | B4: 3 | D4: ml | E4: 3 | G4: coriander | H4: Herbs
A5: Fruits | B5: 4 | D5: l | E5: 4 | G5: berbere spice | H5: Spices
A6: Grains | B6: 5 | D6: tsp | E6: 5 | G6: tomato paste | H6: Condiments
A7: Dairy | B7: 6 | D7: tbsp | E7: 6 | G7: honey | H7: Condiments
A8: Herbs | B8: 7 | D8: each | E8: 7 | G8: apple cider vinegar | H8: Condiments
A9: Spices | B9: 8 | D9: clove | E9: 8 | G9: olive oil | H9: Oils & Fats
A10: Oils & Fats | B10: 9 | D10: piece | E10: 9 | G10: carrots | H10: Vegetables
A11: Condiments | B11: 10 | D11: tin | E11: 10 | G11: tinned chickpeas | H11: Condiments
A12: Nuts & Seeds | B12: 11 | D12: bunch | E12: 11 | G12: chicken thigh | H12: Meat
A13: Seasoning | B13: 12 | G13: oranges | H13: Fruits
A14: Others | B14: 13 | G14: salt | H14: Seasoning
G15: black pepper | H15: Spices
G16: salmon fillet | H16: Seafood
G17: zaatar | H17: Spices
G18: sumac | H18: Spices
G19: baby spinach | H19: Vegetables
G20: tahini | H20: Condiments
G21: lemon juice | H21: Fruits
G22: basmati rice | H22: Grains
G23: unsalted butter | H23: Dairy
G24: boiling water | H24: Others
G25: mint | H25: Herbs
G26: feta | H26: Dairy
... G84: dry sherry | H84: Others

Sheet cookbook_ws
A1: cookbook_title | B1: chef_first_name | C1: chef_last_name | D1: published_date | E1: cookbook_id | F1: full_name
A2: Ottolenghi Test Kitchen | B2: =LEFT(F2, FIND(" ", F2)-1) -> Yotam | C2: =RIGHT(F2,LEN(F2)-FIND(" ", F2)) -> Ottolenghi | D2: =VLOOKUP(A2,Main!$H$4:$J$118,3,FALSE) -> 44483 | E2: 1 | F2: =VLOOKUP(A2,Main!$H$4:$I$118,2,FALSE) -> Yotam Ottolenghi
A3: Ottolenghi SIMPLE | B3: =LEFT(F3, FIND(" ", F3)-1) -> Yotam | C3: =RIGHT(F3,LEN(F3)-FIND(" ", F3)) -> Ottolenghi | D3: =VLOOKUP(A3,Main!$H$4:$J$118,3,FALSE) -> 43377 | E3: 2 | F3: =VLOOKUP(A3,Main!$H$4:$I$118,2,FALSE) -> Yotam Ottolenghi
A4: MEZCLA | B4: =LEFT(F4, FIND(" ", F4)-1) -> Ixta | C4: =RIGHT(F4,LEN(F4)-FIND(" ", F4)) -> Belfrage | D4: =VLOOKUP(A4,Main!$H$4:$J$118,3,FALSE) -> 44756 | E4: 3 | F4: =VLOOKUP(A4,Main!$H$4:$I$118,2,FALSE) -> Ixta Belfrage
A5: Taverna | B5: =LEFT(F5, FIND(" ", F5)-1) -> Georgina | C5: =RIGHT(F5,LEN(F5)-FIND(" ", F5)) -> Hayden | D5: =VLOOKUP(A5,Main!$H$4:$J$118,3,FALSE) -> 45099 | E5: 4 | F5: =VLOOKUP(A5,Main!$H$4:$I$118,2,FALSE) -> Georgina Hayden
A6: Basics To Brilliance Kids | B6: =LEFT(F6, FIND(" ", F6)-1) -> Donna | C6: =RIGHT(F6,LEN(F6)-FIND(" ", F6)) -> Hay | D6: =VLOOKUP(A6,Main!$H$4:$J$118,3,FALSE) -> 43391 | E6: 5 | F6: =VLOOKUP(A6,Main!$H$4:$I$118,2,FALSE) -> Donna Hay
A7: Stirring Slowly | B7: =LEFT(F7, FIND(" ", F7)-1) -> Georgina | C7: =RIGHT(F7,LEN(F7)-FIND(" ", F7)) -> Hayden | D7: =VLOOKUP(A7,Main!$H$4:$J$118,3,FALSE) -> 44987 | E7: 6 | F7: =VLOOKUP(A7,Main!$H$4:$I$118,2,FALSE) -> Georgina Hayden
A8: James Every Day | B8: =LEFT(F8, FIND(" ", F8)-1) -> James | C8: =RIGHT(F8,LEN(F8)-FIND(" ", F8)) -> Martin | D8: =VLOOKUP(A8,Main!$H$4:$J$118,3,FALSE) -> 42985 | E8: 7 | F8: =VLOOKUP(A8,Main!$H$4:$I$118,2,FALSE) -> James Martin
A9: From The Oven To The Table | B9: =LEFT(F9, FIND(" ", F9)-1) -> Diana | C9: =RIGHT(F9,LEN(F9)-FIND(" ", F9)) -> Henry | D9: =VLOOKUP(A9,Main!$H$4:$J$118,3,FALSE) -> 43713 | E9: 8 | F9: =VLOOKUP(A9,Main!$H$4:$I$118,2,FALSE) -> Diana Henry
A10: Delias Happy Christmas | B10: =LEFT(F10, FIND(" ", F10)-1) -> Delia | C10: =RIGHT(F10,LEN(F10)-FIND(" ", F10)) -> Smith | D10: =VLOOKUP(A10,Main!$H$4:$J$118,3,FALSE) -> 40087 | E10: 9 | F10: =VLOOKUP(A10,Main!$H$4:$I$118,2,FALSE) -> Delia Smith

Sheet ingredients_ws
A1: ingredient_name | B1: ingredient_type | C1: ingredient_type_id | D1: ingredient_id
A2: {=_xlfn.UNIQUE(Main!$B$4:$B$134)} -> onion | B2: =VLOOKUP(A2,others!$G$2:$H$84,2,FALSE) -> Vegetables | C2: =VLOOKUP(B2,others!$A$2:$B$14,2,FALSE) -> 3 | D2: 1
A3: garlic clove | B3: =VLOOKUP(A3,others!$G$2:$H$84,2,FALSE) -> Vegetables | C3: =VLOOKUP(B3,others!$A$2:$B$14,2,FALSE) -> 3 | D3: =D2+1 -> 2
A4: coriander | B4: =VLOOKUP(A4,others!$G$2:$H$84,2,FALSE) -> Herbs | C4: =VLOOKUP(B4,others!$A$2:$B$14,2,FALSE) -> 7 | D4: =D3+1 -> 3
A5: berbere spice | B5: =VLOOKUP(A5,others!$G$2:$H$84,2,FALSE) -> Spices | C5: =VLOOKUP(B5,others!$A$2:$B$14,2,FALSE) -> 8 | D5: =D4+1 -> 4
A6: tomato paste | B6: =VLOOKUP(A6,others!$G$2:$H$84,2,FALSE) -> Condiments | C6: =VLOOKUP(B6,others!$A$2:$B$14,2,FALSE) -> 10 | D6: =D5+1 -> 5
A7: honey | B7: =VLOOKUP(A7,others!$G$2:$H$84,2,FALSE) -> Condiments | C7: =VLOOKUP(B7,others!$A$2:$B$14,2,FALSE) -> 10 | D7: =D6+1 -> 6
A8: apple cider vinegar | B8: =VLOOKUP(A8,others!$G$2:$H$84,2,FALSE) -> Condiments | C8: =VLOOKUP(B8,others!$A$2:$B$14,2,FALSE) -> 10 | D8: =D7+1 -> 7
A9: olive oil | B9: =VLOOKUP(A9,others!$G$2:$H$84,2,FALSE) -> Oils & Fats | C9: =VLOOKUP(B9,others!$A$2:$B$14,2,FALSE) -> 9 | D9: =D8+1 -> 8
A10: carrots | B10: =VLOOKUP(A10,others!$G$2:$H$84,2,FALSE) -> Vegetables | C10: =VLOOKUP(B10,others!$A$2:$B$14,2,FALSE) -> 3 | D10: =D9+1 -> 9
A11: tinned chickpeas | B11: =VLOOKUP(A11,others!$G$2:$H$84,2,FALSE) -> Condiments | C11: =VLOOKUP(B11,others!$A$2:$B$14,2,FALSE) -> 10 | D11: =D10+1 -> 10
A12: chicken thigh | B12: =VLOOKUP(A12,others!$G$2:$H$84,2,FALSE) -> Meat | C12: =VLOOKUP(B12,others!$A$2:$B$14,2,FALSE) -> 1 | D12: =D11+1 -> 11
A13: oranges | B13: =VLOOKUP(A13,others!$G$2:$H$84,2,FALSE) -> Fruits | C13: =VLOOKUP(B13,others!$A$2:$B$14,2,FALSE) -> 4 | D13: =D12+1 -> 12
A14: salt | B14: =VLOOKUP(A14,others!$G$2:$H$84,2,FALSE) -> Seasoning | C14: =VLOOKUP(B14,others!$A$2:$B$14,2,FALSE) -> 12 | D14: =D13+1 -> 13
... A84: dry sherry | B84: =VLOOKUP(A84,others!$G$2:$H$84,2,FALSE) -> Others | C84: =VLOOKUP(B84,others!$A$2:$B$14,2,FALSE) -> 13 | D84: =D83+1 -> 83

Sheet recipes_ws
A1: recipe_name | B1: prep_time | C1: cooking_time | D1: cooking_date | E1: cookbook_title | F1: cookbook_id | G1: recipe_id
A2: Berbere spiced chicken | B2: =VLOOKUP($A2,Main!$A$4:$F$118,5,FALSE) -> 0.017361111 | C2: =VLOOKUP($A2,Main!$A$4:$F$118,6,FALSE) -> 0.059027778 | D2: 45942 | E2: =VLOOKUP(A2,Main!$A$4:$H$118,8,FALSE) -> Ottolenghi Test Kitchen | F2: =VLOOKUP(E2,cookbook_ws!$A$2:$E$10,5,FALSE) -> 1 | G2: 1
A3: Zaatar salmon | B3: =VLOOKUP($A3,Main!$A$4:$F$118,5,FALSE) -> 0.0034722222 | C3: =VLOOKUP($A3,Main!$A$4:$F$118,6,FALSE) -> 0.013888889 | D3: 45988 | E3: =VLOOKUP(A3,Main!$A$4:$H$118,8,FALSE) -> Ottolenghi Test Kitchen | F3: =VLOOKUP(E3,cookbook_ws!$A$2:$E$10,5,FALSE) -> 1 | G3: 2
A4: Baked mint rice | B4: =VLOOKUP($A4,Main!$A$4:$F$118,5,FALSE) -> 0.0034722222 | C4: =VLOOKUP($A4,Main!$A$4:$F$118,6,FALSE) -> 0.017361111 | D4: 45988 | E4: =VLOOKUP(A4,Main!$A$4:$H$118,8,FALSE) -> Ottolenghi SIMPLE | F4: =VLOOKUP(E4,cookbook_ws!$A$2:$E$10,5,FALSE) -> 2 | G4: 3
A5: Baked rice with tomato and garlic | B5: =VLOOKUP($A5,Main!$A$4:$F$118,5,FALSE) -> 0.010416667 | C5: =VLOOKUP($A5,Main!$A$4:$F$118,6,FALSE) -> 0.069444444 | D5: 46107 | E5: =VLOOKUP(A5,Main!$A$4:$H$118,8,FALSE) -> Ottolenghi SIMPLE | F5: =VLOOKUP(E5,cookbook_ws!$A$2:$E$10,5,FALSE) -> 2 | G5: 4
A6: TV chips | B6: =VLOOKUP($A6,Main!$A$4:$F$118,5,FALSE) -> 0.0069444444 | C6: =VLOOKUP($A6,Main!$A$4:$F$118,6,FALSE) -> 0.038194444 | D6: 46116 | E6: =VLOOKUP(A6,Main!$A$4:$H$118,8,FALSE) -> MEZCLA | F6: =VLOOKUP(E6,cookbook_ws!$A$2:$E$10,5,FALSE) -> 3 | G6: 5
A7: Portokalopita | B7: =VLOOKUP($A7,Main!$A$4:$F$118,5,FALSE) -> 0.0625 | C7: =VLOOKUP($A7,Main!$A$4:$F$118,6,FALSE) -> 0.055555556 | D7: 46114 | E7: =VLOOKUP(A7,Main!$A$4:$H$118,8,FALSE) -> Taverna | F7: =VLOOKUP(E7,cookbook_ws!$A$2:$E$10,5,FALSE) -> 4 | G7: 6
A8: Blueberry muffins | B8: =VLOOKUP($A8,Main!$A$4:$F$118,5,FALSE) -> 0.0069444444 | C8: =VLOOKUP($A8,Main!$A$4:$F$118,6,FALSE) -> 0.020833333 | D8: 46127 | E8: =VLOOKUP(A8,Main!$A$4:$H$118,8,FALSE) -> Basics To Brilliance Kids | F8: =VLOOKUP(E8,cookbook_ws!$A$2:$E$10,5,FALSE) -> 5 | G8: 7
A9: Roasted aubergine | B9: =VLOOKUP($A9,Main!$A$4:$F$118,5,FALSE) -> 0.0069444444 | C9: =VLOOKUP($A9,Main!$A$4:$F$118,6,FALSE) -> 0.041666667 | D9: 46122 | E9: =VLOOKUP(A9,Main!$A$4:$H$118,8,FALSE) -> Stirring Slowly | F9: =VLOOKUP(E9,cookbook_ws!$A$2:$E$10,5,FALSE) -> 6 | G9: 8
A10: Roast pork | B10: =VLOOKUP($A10,Main!$A$4:$F$118,5,FALSE) -> 0.0069444444 | C10: =VLOOKUP($A10,Main!$A$4:$F$118,6,FALSE) -> 0.083333333 | D10: 46129 | E10: =VLOOKUP(A10,Main!$A$4:$H$118,8,FALSE) -> James Every Day | F10: =VLOOKUP(E10,cookbook_ws!$A$2:$E$10,5,FALSE) -> 7 | G10: 9
A11: Baked Fennel | B11: =VLOOKUP($A11,Main!$A$4:$F$118,5,FALSE) -> 0.0069444444 | C11: =VLOOKUP($A11,Main!$A$4:$F$118,6,FALSE) -> 0.027777778 | D11: 46073 | E11: =VLOOKUP(A11,Main!$A$4:$H$118,8,FALSE) -> From The Oven To The Table | F11: =VLOOKUP(E11,cookbook_ws!$A$2:$E$10,5,FALSE) -> 8 | G11: 10
A12: Wild mushroom & walnut soup | B12: =VLOOKUP($A12,Main!$A$4:$F$118,5,FALSE) -> 0.013888889 | C12: =VLOOKUP($A12,Main!$A$4:$F$118,6,FALSE) -> 0.072916667 | D12: 46013 | E12: =VLOOKUP(A12,Main!$A$4:$H$118,8,FALSE) -> Delias Happy Christmas | F12: =VLOOKUP(E12,cookbook_ws!$A$2:$E$10,5,FALSE) -> 9 | G12: 11

Sheet recipes_ingredients_ws
A1: recipe_name | B1: recipe_id | C1: ingredient_name | D1: ingredient_id | E1: ingredient_quantity | F1: unit_abbreviation | G1: unit_id
A2: {=Main!$A$4:$A$134} -> Berbere spiced chicken | B2: =VLOOKUP(A2,recipes_ws!$A$2:$G$12,7,FALSE) -> 1 | C2: {=Main!$B$4:$B$134} -> onion | D2: =VLOOKUP(C2,ingredients_ws!$A$2:$D$84,4,FALSE) -> 1 | E2: {=Main!$C$4:$C$134} -> 1 | F2: {=Main!$D$4:$D$134} -> each | G2: =VLOOKUP(F2,others!$D$2:$E$12,2,FALSE) -> 7
A3: Berbere spiced chicken | B3: =VLOOKUP(A3,recipes_ws!$A$2:$G$12,7,FALSE) -> 1 | C3: garlic clove | D3: =VLOOKUP(C3,ingredients_ws!$A$2:$D$84,4,FALSE) -> 2 | E3: 6 | F3: clove | G3: =VLOOKUP(F3,others!$D$2:$E$12,2,FALSE) -> 8
A4: Berbere spiced chicken | B4: =VLOOKUP(A4,recipes_ws!$A$2:$G$12,7,FALSE) -> 1 | C4: coriander | D4: =VLOOKUP(C4,ingredients_ws!$A$2:$D$84,4,FALSE) -> 3 | E4: 45 | F4: g | G4: =VLOOKUP(F4,others!$D$2:$E$12,2,FALSE) -> 1
A5: Berbere spiced chicken | B5: =VLOOKUP(A5,recipes_ws!$A$2:$G$12,7,FALSE) -> 1 | C5: berbere spice | D5: =VLOOKUP(C5,ingredients_ws!$A$2:$D$84,4,FALSE) -> 4 | E5: 2.5 | F5: tbsp | G5: =VLOOKUP(F5,others!$D$2:$E$12,2,FALSE) -> 6
A6: Berbere spiced chicken | B6: =VLOOKUP(A6,recipes_ws!$A$2:$G$12,7,FALSE) -> 1 | C6: tomato paste | D6: =VLOOKUP(C6,ingredients_ws!$A$2:$D$84,4,FALSE) -> 5 | E6: 2 | F6: tbsp | G6: =VLOOKUP(F6,others!$D$2:$E$12,2,FALSE) -> 6
A7: Berbere spiced chicken | B7: =VLOOKUP(A7,recipes_ws!$A$2:$G$12,7,FALSE) -> 1 | C7: honey | D7: =VLOOKUP(C7,ingredients_ws!$A$2:$D$84,4,FALSE) -> 6 | E7: 2.5 | F7: tbsp | G7: =VLOOKUP(F7,others!$D$2:$E$12,2,FALSE) -> 6
A8: Berbere spiced chicken | B8: =VLOOKUP(A8,recipes_ws!$A$2:$G$12,7,FALSE) -> 1 | C8: apple cider vinegar | D8: =VLOOKUP(C8,ingredients_ws!$A$2:$D$84,4,FALSE) -> 7 | E8: 3 | F8: tbsp | G8: =VLOOKUP(F8,others!$D$2:$E$12,2,FALSE) -> 6
A9: Berbere spiced chicken | B9: =VLOOKUP(A9,recipes_ws!$A$2:$G$12,7,FALSE) -> 1 | C9: olive oil | D9: =VLOOKUP(C9,ingredients_ws!$A$2:$D$84,4,FALSE) -> 8 | E9: 90 | F9: ml | G9: =VLOOKUP(F9,others!$D$2:$E$12,2,FALSE) -> 3
A10: Berbere spiced chicken | B10: =VLOOKUP(A10,recipes_ws!$A$2:$G$12,7,FALSE) -> 1 | C10: carrots | D10: =VLOOKUP(C10,ingredients_ws!$A$2:$D$84,4,FALSE) -> 9 | E10: 800 | F10: g | G10: =VLOOKUP(F10,others!$D$2:$E$12,2,FALSE) -> 1
A11: Berbere spiced chicken | B11: =VLOOKUP(A11,recipes_ws!$A$2:$G$12,7,FALSE) -> 1 | C11: tinned chickpeas | D11: =VLOOKUP(C11,ingredients_ws!$A$2:$D$84,4,FALSE) -> 10 | E11: 2 | F11: tin | G11: =VLOOKUP(F11,others!$D$2:$E$12,2,FALSE) -> 10
A12: Berbere spiced chicken | B12: =VLOOKUP(A12,recipes_ws!$A$2:$G$12,7,FALSE) -> 1 | C12: chicken thigh | D12: =VLOOKUP(C12,ingredients_ws!$A$2:$D$84,4,FALSE) -> 11 | E12: 8 | F12: piece | G12: =VLOOKUP(F12,others!$D$2:$E$12,2,FALSE) -> 9
A13: Berbere spiced chicken | B13: =VLOOKUP(A13,recipes_ws!$A$2:$G$12,7,FALSE) -> 1 | C13: oranges | D13: =VLOOKUP(C13,ingredients_ws!$A$2:$D$84,4,FALSE) -> 12 | E13: 3 | F13: each | G13: =VLOOKUP(F13,others!$D$2:$E$12,2,FALSE) -> 7
A14: Berbere spiced chicken | B14: =VLOOKUP(A14,recipes_ws!$A$2:$G$12,7,FALSE) -> 1 | C14: salt | D14: =VLOOKUP(C14,ingredients_ws!$A$2:$D$84,4,FALSE) -> 13 | E14: 0.1 | F14: tsp | G14: =VLOOKUP(F14,others!$D$2:$E$12,2,FALSE) -> 5
... A59: TV chips | B59: =VLOOKUP(A59,recipes_ws!$A$2:$G$12,7,FALSE) -> 5 | C59: lemon juice | D59: =VLOOKUP(C59,ingredients_ws!$A$2:$D$84,4,FALSE) -> 20 | E59: 2 | F59: tbsp | G59: =VLOOKUP(F59,others!$D$2:$E$12,2,FALSE) -> 6
A60: TV chips | B60: =VLOOKUP(A60,recipes_ws!$A$2:$G$12,7,FALSE) -> 5 | C60: flaked salt | D60: =VLOOKUP(C60,ingredients_ws!$A$2:$D$84,4,FALSE) -> 35 | E60: 1/2 | F60: tsp | G60: =VLOOKUP(F60,others!$D$2:$E$12,2,FALSE) -> 5
A61: TV chips | B61: =VLOOKUP(A61,recipes_ws!$A$2:$G$12,7,FALSE) -> 5 | C61: double cream | D61: =VLOOKUP(C61,ingredients_ws!$A$2:$D$84,4,FALSE) -> 39 | E61: 4 | F61: tbsp | G61: =VLOOKUP(F61,others!$D$2:$E$12,2,FALSE) -> 6
A62: TV chips | B62: =VLOOKUP(A62,recipes_ws!$A$2:$G$12,7,FALSE) -> 5 | C62: Parmesan | D62: =VLOOKUP(C62,ingredients_ws!$A$2:$D$84,4,FALSE) -> 40 | E62: 15 | F62: g | G62: =VLOOKUP(F62,others!$D$2:$E$12,2,FALSE) -> 1
A63: TV chips | B63: =VLOOKUP(A63,recipes_ws!$A$2:$G$12,7,FALSE) -> 5 | C63: garlic clove | D63: =VLOOKUP(C63,ingredients_ws!$A$2:$D$84,4,FALSE) -> 2 | E63: 1 | F63: clove | G63: =VLOOKUP(F63,others!$D$2:$E$12,2,FALSE) -> 8
A64: TV chips | B64: =VLOOKUP(A64,recipes_ws!$A$2:$G$12,7,FALSE) -> 5 | C64: tomato | D64: =VLOOKUP(C64,ingredients_ws!$A$2:$D$84,4,FALSE) -> 41 | E64: 2 | F64: each | G64: =VLOOKUP(F64,others!$D$2:$E$12,2,FALSE) -> 7
A65: Portokalopita | B65: =VLOOKUP(A65,recipes_ws!$A$2:$G$12,7,FALSE) -> 6 | C65: orange | D65: =VLOOKUP(C65,ingredients_ws!$A$2:$D$84,4,FALSE) -> 42 | E65: 2 | F65: each | G65: =VLOOKUP(F65,others!$D$2:$E$12,2,FALSE) -> 7
A66: Portokalopita | B66: =VLOOKUP(A66,recipes_ws!$A$2:$G$12,7,FALSE) -> 6 | C66: filo | D66: =VLOOKUP(C66,ingredients_ws!$A$2:$D$84,4,FALSE) -> 43 | E66: 500 | F66: g | G66: =VLOOKUP(F66,others!$D$2:$E$12,2,FALSE) -> 1
A67: Portokalopita | B67: =VLOOKUP(A67,recipes_ws!$A$2:$G$12,7,FALSE) -> 6 | C67: caster sugar | D67: =VLOOKUP(C67,ingredients_ws!$A$2:$D$84,4,FALSE) -> 44 | E67: 400 | F67: g | G67: =VLOOKUP(F67,others!$D$2:$E$12,2,FALSE) -> 1
A68: Portokalopita | B68: =VLOOKUP(A68,recipes_ws!$A$2:$G$12,7,FALSE) -> 6 | C68: cinnamon stick | D68: =VLOOKUP(C68,ingredients_ws!$A$2:$D$84,4,FALSE) -> 33 | E68: 1 | F68: each | G68: =VLOOKUP(F68,others!$D$2:$E$12,2,FALSE) -> 7
A69: Portokalopita | B69: =VLOOKUP(A69,recipes_ws!$A$2:$G$12,7,FALSE) -> 6 | C69: olive oil | D69: =VLOOKUP(C69,ingredients_ws!$A$2:$D$84,4,FALSE) -> 8 | E69: 200 | F69: ml | G69: =VLOOKUP(F69,others!$D$2:$E$12,2,FALSE) -> 3
A70: Portokalopita | B70: =VLOOKUP(A70,recipes_ws!$A$2:$G$12,7,FALSE) -> 6 | C70: Greek yoghurt | D70: =VLOOKUP(C70,ingredients_ws!$A$2:$D$84,4,FALSE) -> 45 | E70: 250 | F70: g | G70: =VLOOKUP(F70,others!$D$2:$E$12,2,FALSE) -> 1
A71: Portokalopita | B71: =VLOOKUP(A71,recipes_ws!$A$2:$G$12,7,FALSE) -> 6 | C71: egg | D71: =VLOOKUP(C71,ingredients_ws!$A$2:$D$84,4,FALSE) -> 46 | E71: 5 | F71: each | G71: =VLOOKUP(F71,others!$D$2:$E$12,2,FALSE) -> 7
A72: Portokalopita | B72: =VLOOKUP(A72,recipes_ws!$A$2:$G$12,7,FALSE) -> 6 | C72: baking powder | D72: =VLOOKUP(C72,ingredients_ws!$A$2:$D$84,4,FALSE) -> 47 | E72: 1 | F72: tbsp | G72: =VLOOKUP(F72,others!$D$2:$E$12,2,FALSE) -> 6
... A92: Roasted aubergine | B92: =VLOOKUP(A92,recipes_ws!$A$2:$G$12,7,FALSE) -> 8 | C92: tamarind paste | D92: =VLOOKUP(C92,ingredients_ws!$A$2:$D$84,4,FALSE) -> 60 | E92: 1 | F92: tbsp | G92: =VLOOKUP(F92,others!$D$2:$E$12,2,FALSE) -> 6
A93: Roasted aubergine | B93: =VLOOKUP(A93,recipes_ws!$A$2:$G$12,7,FALSE) -> 8 | C93: honey | D93: =VLOOKUP(C93,ingredients_ws!$A$2:$D$84,4,FALSE) -> 6 | E93: 1/2 | F93: tbsp | G93: =VLOOKUP(F93,others!$D$2:$E$12,2,FALSE) -> 6
A94: Roasted aubergine | B94: =VLOOKUP(A94,recipes_ws!$A$2:$G$12,7,FALSE) -> 8 | C94: miso | D94: =VLOOKUP(C94,ingredients_ws!$A$2:$D$84,4,FALSE) -> 61 | E94: 3 | F94: tbsp | G94: =VLOOKUP(F94,others!$D$2:$E$12,2,FALSE) -> 6
A95: Roast pork | B95: =VLOOKUP(A95,recipes_ws!$A$2:$G$12,7,FALSE) -> 9 | C95: Dijon mustard | D95: =VLOOKUP(C95,ingredients_ws!$A$2:$D$84,4,FALSE) -> 62 | E95: 2 | F95: tbsp | G95: =VLOOKUP(F95,others!$D$2:$E$12,2,FALSE) -> 6
A96: Roast pork | B96: =VLOOKUP(A96,recipes_ws!$A$2:$G$12,7,FALSE) -> 9 | C96: honey | D96: =VLOOKUP(C96,ingredients_ws!$A$2:$D$84,4,FALSE) -> 6 | E96: 2 | F96: tbsp | G96: =VLOOKUP(F96,others!$D$2:$E$12,2,FALSE) -> 6
A97: Roast pork | B97: =VLOOKUP(A97,recipes_ws!$A$2:$G$12,7,FALSE) -> 9 | C97: pork joint | D97: =VLOOKUP(C97,ingredients_ws!$A$2:$D$84,4,FALSE) -> 63 | E97: 1.3 | F97: kg | G97: =VLOOKUP(F97,others!$D$2:$E$12,2,FALSE) -> 2
A98: Roast pork | B98: =VLOOKUP(A98,recipes_ws!$A$2:$G$12,7,FALSE) -> 9 | C98: chicken stock | D98: =VLOOKUP(C98,ingredients_ws!$A$2:$D$84,4,FALSE) -> 64 | E98: 500 | F98: ml | G98: =VLOOKUP(F98,others!$D$2:$E$12,2,FALSE) -> 3
A99: Roast pork | B99: =VLOOKUP(A99,recipes_ws!$A$2:$G$12,7,FALSE) -> 9 | C99: balsamic vinegar | D99: =VLOOKUP(C99,ingredients_ws!$A$2:$D$84,4,FALSE) -> 65 | E99: 2 | F99: tbsp | G99: =VLOOKUP(F99,others!$D$2:$E$12,2,FALSE) -> 6
A100: Roast pork | B100: =VLOOKUP(A100,recipes_ws!$A$2:$G$12,7,FALSE) -> 9 | C100: tinned butter beans | D100: =VLOOKUP(C100,ingredients_ws!$A$2:$D$84,4,FALSE) -> 66 | E100: 400 | F100: g | G100: =VLOOKUP(F100,others!$D$2:$E$12,2,FALSE) -> 1
A101: Roast pork | B101: =VLOOKUP(A101,recipes_ws!$A$2:$G$12,7,FALSE) -> 9 | C101: butter | D101: =VLOOKUP(C101,ingredients_ws!$A$2:$D$84,4,FALSE) -> 67 | E101: 20 | F101: g | G101: =VLOOKUP(F101,others!$D$2:$E$12,2,FALSE) -> 1
A102: Roast pork | B102: =VLOOKUP(A102,recipes_ws!$A$2:$G$12,7,FALSE) -> 9 | C102: parsley | D102: =VLOOKUP(C102,ingredients_ws!$A$2:$D$84,4,FALSE) -> 68 | E102: 10 | F102: g | G102: =VLOOKUP(F102,others!$D$2:$E$12,2,FALSE) -> 1
A103: Roast pork | B103: =VLOOKUP(A103,recipes_ws!$A$2:$G$12,7,FALSE) -> 9 | C103: oregano | D103: =VLOOKUP(C103,ingredients_ws!$A$2:$D$84,4,FALSE) -> 69 | E103: 5 | F103: g | G103: =VLOOKUP(F103,others!$D$2:$E$12,2,FALSE) -> 1
...

Sheet stocks_ws
A1: ingredient_name | B1: ingredient_id | C1: stock_quantity | D1: unit_abbbreviation | E1: unit_id | F1: is_available
A2: {=_xlfn.ANCHORARRAY(ingredients_ws!A2)} -> onion | B2: =VLOOKUP(A2,ingredients_ws!$A$2:$D$84,4,FALSE) -> 1 | C2: =SUM(VLOOKUP(A2,recipes_ingredients_ws!C2:E1324,3,FALSE)) -> 1 | D2: {=_xlfn.UNIQUE(VLOOKUP(A2,recipes_ingredients_ws!$C$2:$F$132,4,FALSE))} -> each | E2: =VLOOKUP(D2,others!$D$2:$E$12,2,FALSE) -> 7 | F2: 1
A3: garlic clove | B3: =VLOOKUP(A3,ingredients_ws!$A$2:$D$84,4,FALSE) -> 2 | C3: =SUM(VLOOKUP(A3,recipes_ingredients_ws!C3:E1325,3,FALSE)) -> 6 | D3: {=_xlfn.UNIQUE(VLOOKUP(A3,recipes_ingredients_ws!$C$2:$F$132,4,FALSE))} -> clove | E3: =VLOOKUP(D3,others!$D$2:$E$12,2,FALSE) -> 8 | F3: 1
A4: coriander | B4: =VLOOKUP(A4,ingredients_ws!$A$2:$D$84,4,FALSE) -> 3 | C4: =SUM(VLOOKUP(A4,recipes_ingredients_ws!C4:E1326,3,FALSE)) -> 45 | D4: {=_xlfn.UNIQUE(VLOOKUP(A4,recipes_ingredients_ws!$C$2:$F$132,4,FALSE))} -> g | E4: =VLOOKUP(D4,others!$D$2:$E$12,2,FALSE) -> 1 | F4: 1
A5: berbere spice | B5: =VLOOKUP(A5,ingredients_ws!$A$2:$D$84,4,FALSE) -> 4 | C5: =SUM(VLOOKUP(A5,recipes_ingredients_ws!C5:E1327,3,FALSE)) -> 2.5 | D5: {=_xlfn.UNIQUE(VLOOKUP(A5,recipes_ingredients_ws!$C$2:$F$132,4,FALSE))} -> tbsp | E5: =VLOOKUP(D5,others!$D$2:$E$12,2,FALSE) -> 6 | F5: 1
A6: tomato paste | B6: =VLOOKUP(A6,ingredients_ws!$A$2:$D$84,4,FALSE) -> 5 | C6: =SUM(VLOOKUP(A6,recipes_ingredients_ws!C6:E1328,3,FALSE)) -> 2 | D6: {=_xlfn.UNIQUE(VLOOKUP(A6,recipes_ingredients_ws!$C$2:$F$132,4,FALSE))} -> tbsp | E6: =VLOOKUP(D6,others!$D$2:$E$12,2,FALSE) -> 6 | F6: 1
A7: honey | B7: =VLOOKUP(A7,ingredients_ws!$A$2:$D$84,4,FALSE) -> 6 | C7: =SUM(VLOOKUP(A7,recipes_ingredients_ws!C7:E1329,3,FALSE)) -> 2.5 | D7: {=_xlfn.UNIQUE(VLOOKUP(A7,recipes_ingredients_ws!$C$2:$F$132,4,FALSE))} -> tbsp | E7: =VLOOKUP(D7,others!$D$2:$E$12,2,FALSE) -> 6 | F7: 1
A8: apple cider vinegar | B8: =VLOOKUP(A8,ingredients_ws!$A$2:$D$84,4,FALSE) -> 7 | C8: =SUM(VLOOKUP(A8,recipes_ingredients_ws!C8:E1330,3,FALSE)) -> 3 | D8: {=_xlfn.UNIQUE(VLOOKUP(A8,recipes_ingredients_ws!$C$2:$F$132,4,FALSE))} -> tbsp | E8: =VLOOKUP(D8,others!$D$2:$E$12,2,FALSE) -> 6 | F8: 1
A9: olive oil | B9: =VLOOKUP(A9,ingredients_ws!$A$2:$D$84,4,FALSE) -> 8 | C9: =SUM(VLOOKUP(A9,recipes_ingredients_ws!C9:E1331,3,FALSE)) -> 90 | D9: {=_xlfn.UNIQUE(VLOOKUP(A9,recipes_ingredients_ws!$C$2:$F$132,4,FALSE))} -> ml | E9: =VLOOKUP(D9,others!$D$2:$E$12,2,FALSE) -> 3 | F9: 1
A10: carrots | B10: =VLOOKUP(A10,ingredients_ws!$A$2:$D$84,4,FALSE) -> 9 | C10: =SUM(VLOOKUP(A10,recipes_ingredients_ws!C10:E1332,3,FALSE)) -> 800 | D10: {=_xlfn.UNIQUE(VLOOKUP(A10,recipes_ingredients_ws!$C$2:$F$132,4,FALSE))} -> g | E10: =VLOOKUP(D10,others!$D$2:$E$12,2,FALSE) -> 1 | F10: 1
A11: tinned chickpeas | B11: =VLOOKUP(A11,ingredients_ws!$A$2:$D$84,4,FALSE) -> 10 | C11: =SUM(VLOOKUP(A11,recipes_ingredients_ws!C11:E1333,3,FALSE)) -> 2 | D11: {=_xlfn.UNIQUE(VLOOKUP(A11,recipes_ingredients_ws!$C$2:$F$132,4,FALSE))} -> tin | E11: =VLOOKUP(D11,others!$D$2:$E$12,2,FALSE) -> 10 | F11: 1
A12: chicken thigh | B12: =VLOOKUP(A12,ingredients_ws!$A$2:$D$84,4,FALSE) -> 11 | C12: =SUM(VLOOKUP(A12,recipes_ingredients_ws!C12:E1334,3,FALSE)) -> 8 | D12: {=_xlfn.UNIQUE(VLOOKUP(A12,recipes_ingredients_ws!$C$2:$F$132,4,FALSE))} -> piece | E12: =VLOOKUP(D12,others!$D$2:$E$12,2,FALSE) -> 9 | F12: 1
A13: oranges | B13: =VLOOKUP(A13,ingredients_ws!$A$2:$D$84,4,FALSE) -> 12 | C13: =SUM(VLOOKUP(A13,recipes_ingredients_ws!C13:E1335,3,FALSE)) -> 3 | D13: {=_xlfn.UNIQUE(VLOOKUP(A13,recipes_ingredients_ws!$C$2:$F$132,4,FALSE))} -> each | E13: =VLOOKUP(D13,others!$D$2:$E$12,2,FALSE) -> 7 | F13: 1
A14: salt | B14: =VLOOKUP(A14,ingredients_ws!$A$2:$D$84,4,FALSE) -> 13 | C14: =SUM(VLOOKUP(A14,recipes_ingredients_ws!C14:E1336,3,FALSE)) -> 0.1 | D14: {=_xlfn.UNIQUE(VLOOKUP(A14,recipes_ingredients_ws!$C$2:$F$132,4,FALSE))} -> tsp | E14: =VLOOKUP(D14,others!$D$2:$E$12,2,FALSE) -> 5 | F14: 1
... A84: dry sherry | B84: =VLOOKUP(A84,ingredients_ws!$A$2:$D$84,4,FALSE) -> 83 | C84: =SUM(VLOOKUP(A84,recipes_ingredients_ws!C84:E1406,3,FALSE)) -> 75 | D84: {=_xlfn.UNIQUE(VLOOKUP(A84,recipes_ingredients_ws!$C$2:$F$132,4,FALSE))} -> ml | E84: =VLOOKUP(D84,others!$D$2:$E$12,2,FALSE) -> 3 | F84: 1

Sheet cookbook_table
A1: =_xlfn.CONCAT("'",LOWER(cookbook_ws!A1),"'") -> 'cookbook_title' | B1: =_xlfn.CONCAT("'",LOWER(cookbook_ws!B1),"'") -> 'chef_first_name' | C1: =_xlfn.CONCAT("'",LOWER(cookbook_ws!C1),"'") -> 'chef_last_name' | D1: =_xlfn.CONCAT("'",LOWER(cookbook_ws!D1),"'") -> 'published_date'
A2: =_xlfn.CONCAT("'",LOWER(cookbook_ws!A2),"'") -> 'ottolenghi test kitchen' | B2: =_xlfn.CONCAT("'",LOWER(cookbook_ws!B2),"'") -> 'yotam' | C2: =_xlfn.CONCAT("'",LOWER(cookbook_ws!C2),"'") -> 'ottolenghi' | D2: =cookbook_ws!D2 -> 44483
A3: =_xlfn.CONCAT("'",LOWER(cookbook_ws!A3),"'") -> 'ottolenghi simple' | B3: =_xlfn.CONCAT("'",LOWER(cookbook_ws!B3),"'") -> 'yotam' | C3: =_xlfn.CONCAT("'",LOWER(cookbook_ws!C3),"'") -> 'ottolenghi' | D3: =cookbook_ws!D3 -> 43377
A4: =_xlfn.CONCAT("'",LOWER(cookbook_ws!A4),"'") -> 'mezcla' | B4: =_xlfn.CONCAT("'",LOWER(cookbook_ws!B4),"'") -> 'ixta' | C4: =_xlfn.CONCAT("'",LOWER(cookbook_ws!C4),"'") -> 'belfrage' | D4: =cookbook_ws!D4 -> 44756
A5: =_xlfn.CONCAT("'",LOWER(cookbook_ws!A5),"'") -> 'taverna' | B5: =_xlfn.CONCAT("'",LOWER(cookbook_ws!B5),"'") -> 'georgina' | C5: =_xlfn.CONCAT("'",LOWER(cookbook_ws!C5),"'") -> 'hayden' | D5: =cookbook_ws!D5 -> 45099
A6: =_xlfn.CONCAT("'",LOWER(cookbook_ws!A6),"'") -> 'basics to brilliance kids' | B6: =_xlfn.CONCAT("'",LOWER(cookbook_ws!B6),"'") -> 'donna' | C6: =_xlfn.CONCAT("'",LOWER(cookbook_ws!C6),"'") -> 'hay' | D6: =cookbook_ws!D6 -> 43391
A7: =_xlfn.CONCAT("'",LOWER(cookbook_ws!A7),"'") -> 'stirring slowly' | B7: =_xlfn.CONCAT("'",LOWER(cookbook_ws!B7),"'") -> 'georgina' | C7: =_xlfn.CONCAT("'",LOWER(cookbook_ws!C7),"'") -> 'hayden' | D7: =cookbook_ws!D7 -> 44987
A8: =_xlfn.CONCAT("'",LOWER(cookbook_ws!A8),"'") -> 'james every day' | B8: =_xlfn.CONCAT("'",LOWER(cookbook_ws!B8),"'") -> 'james' | C8: =_xlfn.CONCAT("'",LOWER(cookbook_ws!C8),"'") -> 'martin' | D8: =cookbook_ws!D8 -> 42985
A9: =_xlfn.CONCAT("'",LOWER(cookbook_ws!A9),"'") -> 'from the oven to the table' | B9: =_xlfn.CONCAT("'",LOWER(cookbook_ws!B9),"'") -> 'diana' | C9: =_xlfn.CONCAT("'",LOWER(cookbook_ws!C9),"'") -> 'henry' | D9: =cookbook_ws!D9 -> 43713
A10: =_xlfn.CONCAT("'",LOWER(cookbook_ws!A10),"'") -> 'delias happy christmas' | B10: =_xlfn.CONCAT("'",LOWER(cookbook_ws!B10),"'") -> 'delia' | C10: =_xlfn.CONCAT("'",LOWER(cookbook_ws!C10),"'") -> 'smith' | D10: =cookbook_ws!D10 -> 40087

Sheet ingredients_types_table
A1: =_xlfn.CONCAT("'",LOWER(others!A1),"'") -> 'ingredient_type'
A2: =_xlfn.CONCAT("'",LOWER(others!A2),"'") -> 'meat'
A3: =_xlfn.CONCAT("'",LOWER(others!A3),"'") -> 'seafood'
A4: =_xlfn.CONCAT("'",LOWER(others!A4),"'") -> 'vegetables'
A5: =_xlfn.CONCAT("'",LOWER(others!A5),"'") -> 'fruits'
A6: =_xlfn.CONCAT("'",LOWER(others!A6),"'") -> 'grains'
A7: =_xlfn.CONCAT("'",LOWER(others!A7),"'") -> 'dairy'
A8: =_xlfn.CONCAT("'",LOWER(others!A8),"'") -> 'herbs'
A9: =_xlfn.CONCAT("'",LOWER(others!A9),"'") -> 'spices'
A10: =_xlfn.CONCAT("'",LOWER(others!A10),"'") -> 'oils & fats'
A11: =_xlfn.CONCAT("'",LOWER(others!A11),"'") -> 'condiments'
A12: =_xlfn.CONCAT("'",LOWER(others!A12),"'") -> 'nuts & seeds'
... A14: =_xlfn.CONCAT("'",LOWER(others!A14),"'") -> 'others'

Sheet units_table
A1: =_xlfn.CONCAT("'",LOWER(others!D1),"'") -> 'unit_abbreviation'
A2: =_xlfn.CONCAT("'",LOWER(others!D2),"'") -> 'g'
A3: =_xlfn.CONCAT("'",LOWER(others!D3),"'") -> 'kg'
A4: =_xlfn.CONCAT("'",LOWER(others!D4),"'") -> 'ml'
A5: =_xlfn.CONCAT("'",LOWER(others!D5),"'") -> 'l'
A6: =_xlfn.CONCAT("'",LOWER(others!D6),"'") -> 'tsp'
A7: =_xlfn.CONCAT("'",LOWER(others!D7),"'") -> 'tbsp'
A8: =_xlfn.CONCAT("'",LOWER(others!D8),"'") -> 'each'
A9: =_xlfn.CONCAT("'",LOWER(others!D9),"'") -> 'clove'
A10: =_xlfn.CONCAT("'",LOWER(others!D10),"'") -> 'piece'
A11: =_xlfn.CONCAT("'",LOWER(others!D11),"'") -> 'tin'
A12: =_xlfn.CONCAT("'",LOWER(others!D12),"'") -> 'bunch'

Sheet ingredients_table
A1: =LOWER(ingredients_ws!$A1) -> ingredient_name | B1: =LOWER(ingredients_ws!$C1) -> ingredient_type_id
A2: =LOWER(ingredients_ws!$A2) -> onion | B2: =ingredients_ws!$C2 -> 3
A3: =LOWER(ingredients_ws!$A3) -> garlic clove | B3: =ingredients_ws!$C3 -> 3
A4: =LOWER(ingredients_ws!$A4) -> coriander | B4: =ingredients_ws!$C4 -> 7
A5: =LOWER(ingredients_ws!$A5) -> berbere spice | B5: =ingredients_ws!$C5 -> 8
A6: =LOWER(ingredients_ws!$A6) -> tomato paste | B6: =ingredients_ws!$C6 -> 10
A7: =LOWER(ingredients_ws!$A7) -> honey | B7: =ingredients_ws!$C7 -> 10
A8: =LOWER(ingredients_ws!$A8) -> apple cider vinegar | B8: =ingredients_ws!$C8 -> 10
A9: =LOWER(ingredients_ws!$A9) -> olive oil | B9: =ingredients_ws!$C9 -> 9
A10: =LOWER(ingredients_ws!$A10) -> carrots | B10: =ingredients_ws!$C10 -> 3
A11: =LOWER(ingredients_ws!$A11) -> tinned chickpeas | B11: =ingredients_ws!$C11 -> 10
A12: =LOWER(ingredients_ws!$A12) -> chicken thigh | B12: =ingredients_ws!$C12 -> 1
A13: =LOWER(ingredients_ws!$A13) -> oranges | B13: =ingredients_ws!$C13 -> 4
... A84: =LOWER(ingredients_ws!$A84) -> dry sherry | B84: =ingredients_ws!$C84 -> 13

Sheet recipes_table
A1: =LOWER(recipes_ws!A1) -> recipe_name | B1: =LOWER(recipes_ws!B1) -> prep_time | C1: =LOWER(recipes_ws!C1) -> cooking_time | D1: =LOWER(recipes_ws!D1) -> cooking_date | E1: =LOWER(recipes_ws!F1) -> cookbook_id
A2: =LOWER(recipes_ws!A2) -> berbere spiced chicken | B2: =recipes_ws!B2 -> 0.017361111 | C2: =recipes_ws!C2 -> 0.059027778 | D2: =recipes_ws!D2 -> 45942 | E2: =recipes_ws!F2 -> 1
A3: =LOWER(recipes_ws!A3) -> zaatar salmon | B3: =recipes_ws!B3 -> 0.0034722222 | C3: =recipes_ws!C3 -> 0.013888889 | D3: =recipes_ws!D3 -> 45988 | E3: =recipes_ws!F3 -> 1
A4: =LOWER(recipes_ws!A4) -> baked mint rice | B4: =recipes_ws!B4 -> 0.0034722222 | C4: =recipes_ws!C4 -> 0.017361111 | D4: =recipes_ws!D4 -> 45988 | E4: =recipes_ws!F4 -> 2
A5: =LOWER(recipes_ws!A5) -> baked rice with tomato and garlic | B5: =recipes_ws!B5 -> 0.010416667 | C5: =recipes_ws!C5 -> 0.069444444 | D5: =recipes_ws!D5 -> 46107 | E5: =recipes_ws!F5 -> 2
A6: =LOWER(recipes_ws!A6) -> tv chips | B6: =recipes_ws!B6 -> 0.0069444444 | C6: =recipes_ws!C6 -> 0.038194444 | D6: =recipes_ws!D6 -> 46116 | E6: =recipes_ws!F6 -> 3
A7: =LOWER(recipes_ws!A7) -> portokalopita | B7: =recipes_ws!B7 -> 0.0625 | C7: =recipes_ws!C7 -> 0.055555556 | D7: =recipes_ws!D7 -> 46114 | E7: =recipes_ws!F7 -> 4
A8: =LOWER(recipes_ws!A8) -> blueberry muffins | B8: =recipes_ws!B8 -> 0.0069444444 | C8: =recipes_ws!C8 -> 0.020833333 | D8: =recipes_ws!D8 -> 46127 | E8: =recipes_ws!F8 -> 5
A9: =LOWER(recipes_ws!A9) -> roasted aubergine | B9: =recipes_ws!B9 -> 0.0069444444 | C9: =recipes_ws!C9 -> 0.041666667 | D9: =recipes_ws!D9 -> 46122 | E9: =recipes_ws!F9 -> 6
A10: =LOWER(recipes_ws!A10) -> roast pork | B10: =recipes_ws!B10 -> 0.0069444444 | C10: =recipes_ws!C10 -> 0.083333333 | D10: =recipes_ws!D10 -> 46129 | E10: =recipes_ws!F10 -> 7
A11: =LOWER(recipes_ws!A11) -> baked fennel | B11: =recipes_ws!B11 -> 0.0069444444 | C11: =recipes_ws!C11 -> 0.027777778 | D11: =recipes_ws!D11 -> 46073 | E11: =recipes_ws!F11 -> 8
A12: =LOWER(recipes_ws!A12) -> wild mushroom & walnut soup | B12: =recipes_ws!B12 -> 0.013888889 | C12: =recipes_ws!C12 -> 0.072916667 | D12: =recipes_ws!D12 -> 46013 | E12: =recipes_ws!F12 -> 9

Sheet recipes_ingredients_table
A1: =recipes_ingredients_ws!$B1 -> recipe_id | B1: =recipes_ingredients_ws!$D1 -> ingredient_id | C1: =recipes_ingredients_ws!$E1 -> ingredient_quantity | D1: =recipes_ingredients_ws!$G1 -> unit_id
A2: =recipes_ingredients_ws!$B2 -> 1 | B2: =recipes_ingredients_ws!$D2 -> 1 | C2: =recipes_ingredients_ws!$E2 -> 1 | D2: =recipes_ingredients_ws!$G2 -> 7
A3: =recipes_ingredients_ws!$B3 -> 1 | B3: =recipes_ingredients_ws!$D3 -> 2 | C3: =recipes_ingredients_ws!$E3 -> 6 | D3: =recipes_ingredients_ws!$G3 -> 8
A4: =recipes_ingredients_ws!$B4 -> 1 | B4: =recipes_ingredients_ws!$D4 -> 3 | C4: =recipes_ingredients_ws!$E4 -> 45 | D4: =recipes_ingredients_ws!$G4 -> 1
A5: =recipes_ingredients_ws!$B5 -> 1 | B5: =recipes_ingredients_ws!$D5 -> 4 | C5: =recipes_ingredients_ws!$E5 -> 2.5 | D5: =recipes_ingredients_ws!$G5 -> 6
A6: =recipes_ingredients_ws!$B6 -> 1 | B6: =recipes_ingredients_ws!$D6 -> 5 | C6: =recipes_ingredients_ws!$E6 -> 2 | D6: =recipes_ingredients_ws!$G6 -> 6
A7: =recipes_ingredients_ws!$B7 -> 1 | B7: =recipes_ingredients_ws!$D7 -> 6 | C7: =recipes_ingredients_ws!$E7 -> 2.5 | D7: =recipes_ingredients_ws!$G7 -> 6
A8: =recipes_ingredients_ws!$B8 -> 1 | B8: =recipes_ingredients_ws!$D8 -> 7 | C8: =recipes_ingredients_ws!$E8 -> 3 | D8: =recipes_ingredients_ws!$G8 -> 6
A9: =recipes_ingredients_ws!$B9 -> 1 | B9: =recipes_ingredients_ws!$D9 -> 8 | C9: =recipes_ingredients_ws!$E9 -> 90 | D9: =recipes_ingredients_ws!$G9 -> 3
A10: =recipes_ingredients_ws!$B10 -> 1 | B10: =recipes_ingredients_ws!$D10 -> 9 | C10: =recipes_ingredients_ws!$E10 -> 800 | D10: =recipes_ingredients_ws!$G10 -> 1
A11: =recipes_ingredients_ws!$B11 -> 1 | B11: =recipes_ingredients_ws!$D11 -> 10 | C11: =recipes_ingredients_ws!$E11 -> 2 | D11: =recipes_ingredients_ws!$G11 -> 10
A12: =recipes_ingredients_ws!$B12 -> 1 | B12: =recipes_ingredients_ws!$D12 -> 11 | C12: =recipes_ingredients_ws!$E12 -> 8 | D12: =recipes_ingredients_ws!$G12 -> 9
... A132: =recipes_ingredients_ws!$B132 -> 11 | B132: =recipes_ingredients_ws!$D132 -> 20 | C132: =recipes_ingredients_ws!$E132 -> 10 | D132: =recipes_ingredients_ws!$G132 -> 3

Sheet stocks_table
A1: =LOWER(stocks_ws!$B1) -> ingredient_id | B1: =LOWER(stocks_ws!$C1) -> stock_quantity | C1: =LOWER(stocks_ws!$E1) -> unit_id | D1: =LOWER(stocks_ws!$F1) -> is_available
A2: =stocks_ws!$B2 -> 1 | B2: =stocks_ws!$C2 -> 1 | C2: =stocks_ws!$E2 -> 7 | D2: =stocks_ws!$F2 -> 1
A3: =stocks_ws!$B3 -> 2 | B3: =stocks_ws!$C3 -> 6 | C3: =stocks_ws!$E3 -> 8 | D3: =stocks_ws!$F3 -> 1
A4: =stocks_ws!$B4 -> 3 | B4: =stocks_ws!$C4 -> 45 | C4: =stocks_ws!$E4 -> 1 | D4: =stocks_ws!$F4 -> 1
A5: =stocks_ws!$B5 -> 4 | B5: =stocks_ws!$C5 -> 2.5 | C5: =stocks_ws!$E5 -> 6 | D5: =stocks_ws!$F5 -> 1
A6: =stocks_ws!$B6 -> 5 | B6: =stocks_ws!$C6 -> 2 | C6: =stocks_ws!$E6 -> 6 | D6: =stocks_ws!$F6 -> 1
A7: =stocks_ws!$B7 -> 6 | B7: =stocks_ws!$C7 -> 2.5 | C7: =stocks_ws!$E7 -> 6 | D7: =stocks_ws!$F7 -> 1
A8: =stocks_ws!$B8 -> 7 | B8: =stocks_ws!$C8 -> 3 | C8: =stocks_ws!$E8 -> 6 | D8: =stocks_ws!$F8 -> 1
A9: =stocks_ws!$B9 -> 8 | B9: =stocks_ws!$C9 -> 90 | C9: =stocks_ws!$E9 -> 3 | D9: =stocks_ws!$F9 -> 1
A10: =stocks_ws!$B10 -> 9 | B10: =stocks_ws!$C10 -> 800 | C10: =stocks_ws!$E10 -> 1 | D10: =stocks_ws!$F10 -> 1
A11: =stocks_ws!$B11 -> 10 | B11: =stocks_ws!$C11 -> 2 | C11: =stocks_ws!$E11 -> 10 | D11: =stocks_ws!$F11 -> 1
A12: =stocks_ws!$B12 -> 11 | B12: =stocks_ws!$C12 -> 8 | C12: =stocks_ws!$E12 -> 9 | D12: =stocks_ws!$F12 -> 1
A13: =stocks_ws!$B13 -> 12 | B13: =stocks_ws!$C13 -> 3 | C13: =stocks_ws!$E13 -> 7 | D13: =stocks_ws!$F13 -> 1
... A84: =stocks_ws!$B84 -> 83 | B84: =stocks_ws!$C84 -> 75 | C84: =stocks_ws!$E84 -> 3 | D84: =stocks_ws!$F84 -> 1
